Workbook
Name AGROCHEMICAL: #REF!
Name Base_year: #REF!
Name BAU_Absolute: OFFSET(#REF!,0,0,DCOUNTA(#REF!,"BAU Absolute",#REF!))
Name BAU_Absolute_S3: OFFSET(#REF!,0,0,DCOUNTA(#REF!,"BAU Absolute S3",#REF!))
Name BAU_Intensity: OFFSET(#REF!,0,0, DCOUNTA(#REF!,"BAU Intensity",#REF!))
Name BAU_Intensity_S3: OFFSET(#REF!,0,0,DCOUNTA(#REF!,"BAU Intensity S3",#REF!))
Name Col_Abs_Emissions: #REF!
Name Col_activity: #REF!
Name Col_activity_target: #REF!
Name Col_Company_Intensity: #REF!
Name Col_IEA_Conv: #REF!
Name Col_IEA_data: #REF!
Name Col_index: #REF!
Name Col_input_data: #REF!
Name Col_My: #REF!
Name Col_Sect_Intens: #REF!
Name CommentsRequired: #REF!
Name COUNTRY: #REF!
Name Date: OFFSET(#REF!,0,0, DCOUNTA(#REF!,"Date",#REF!))
Name dererere: #REF!
Name Distance: #REF!
Name DistanceType: #REF!
Name edgeCAT: #REF!
Name EmissionsFactor: #REF!
Name EmissionsFactorRegion: #REF!
Name EmissionsFactorType: #REF!
Name FUEL: #REF!
Name Fuels: #REF!
Name FUELSOURCE: #REF!
Name Land: #REF!
Name Lst_activity_corporate: #REF!
Name Lst_activity_fleet: #REF!
Name Lst_activity_mobile_network: #REF!
Name Lst_activity_total: #REF!
Name Lst_geos: #REF!
Name Lst_Scope_fleet: #REF!
Name Lst_scope1: #REF!
Name Lst_Scope1_2: #REF!
Name Lst_Scope1_2_3: #REF!
Name Lst_scope2: #REF!
Name Lst_Scope3: #REF!
Name Lst_SDA_mapping: #REF!
Name Lst_SDA_sectors: #REF!
Name Lst_sectors: #REF!
Name MinD: #REF!
Name MinF: #REF!
Name MinM: #REF!
Name noABN: #REF!
Name PJ_to_TWh: #REF!
Name Renewable_energy: #REF!
Name Row_Abs_Emissions: #REF!
Name Row_activity: #REF!
Name Row_activity_target: #REF!
Name Row_Company_Intensity: #REF!
Name Row_IEA_conv: #REF!
Name Row_IEA_data: #REF!
Name Row_index: #REF!
Name Row_input_data: #REF!
Name Row_My: #REF!
Name Row_Sect_Intens: #REF!

Sheet 2022 Estimado
G1: 2022 | H1: 2022
B2: VISTA 1: 2022 ESTIMADO | G2: Estimado | H2: Real
B3: Categorias segun impacto en toneladas | C3: 2021 | D3: 2022 estimado | E3: 2022 real | F3: Dif 2022 estimado | G3: kgCO2/pieza | H3: kgCO2/pieza | I3: Dif | K3: Explicación
A4: 1 | B4: Cat 1: Transporte aéreo | C4: 10258.876 | D4: 7308 | E4: 6789 | F4: =+E4-D4 -> -519 | G4: =+D4*1000/$D$23 -> 0.38250097 | H4: =+E4*1000/$D$23 -> 0.35533649 | I4: =+H4-G4 -> -0.027164478 | J4: =+H4/G4-1 -> -0.071018062 | K4: Modifiación en la metodología para las emisiones generadas por LATAM Airlines
A5: 2 | B5: Cat 1: Distribución | C5: 10099.541 | D5: 6681 | E5: 6937 | F5: =+E5-D5 -> 256 | G5: =+D5*1000/$D$23 -> 0.34968377 | H5: =+E5*1000/$D$23 -> 0.36308282 | I5: =+H5-G5 -> 0.013399049 | J5: =+H5/G5-1 -> 0.038317617 | K5: Cambio metodologico, se incluye distribución realizada por flota propia
A6: 3 | B6: Cat 1: Bienes y servicios - Compra de servicios e insumos | C6: 6615.4766 | D6: 5236 | E6: ='5. Bienes y servicios'!$O$35 -> 4140.204 | F6: =+E6-D6 -> -1095.796 | G6: =+D6*1000/$D$23 -> 0.27405242 | H6: =+E6*1000/$D$23 -> 0.21669842 | I6: =+H6-G6 -> -0.057353998 | J6: =+H6/G6-1 -> -0.20928112 | K6: Cambio metodologico, se recategorizan cuentas con equipo de finanzas
A7: 4 | B7: Cat 1: Transporte terrestre terceros - troncal | C7: 11041.988 | D7: 9671 | E7: 4359 | F7: =+E7-D7 -> -5312 | G7: =+D7*1000/$D$23 -> 0.50618047 | H7: =+E7*1000/$D$23 -> 0.22815021 | I7: =+H7-G7 -> -0.27803026 | J7: =+H7/G7-1 -> -0.54927102 | K7: Cambio metodologico,se incluye flota troncal propia y se calculan las emisiones con fuente de información distinta (reporte área de transporte)
A8: 5 | B8: Cat 7: Traslado de trabajadores | C8: 4424.3687 | D8: 3221 | E8: ='6. Traslado colaboradores'!$L$12 -> 3248 | F8: =+E8-D8 -> 27 | G8: =+D8*1000/$D$23 -> 0.16858725 | H8: =+E8*1000/$D$23 -> 0.17000043 | I8: =+H8-G8 -> 0.0014131809 | J8: =+H8/G8-1 -> 0.0083824899 | K8: Cambio metodologico, estimación realizada en basea emisión por colaborador 2021, 2022 en basea encuesta fe hábitos de transporte pa el año de calculo
A9: 6 | B9: Transporte propio | C9: 0 | D9: 0 | E9: 0 | F9: =+E9-D9 -> 0 | G9: =+D9*1000/$D$23 -> 0 | H9: =+E9*1000/$D$23 -> 0 | I9: =+H9-G9 -> 0 | J9: 0 | K9: Desaparece esta categoría y su impacto se refleja en las categorías de distribución y transporte troncal
A10: 7 | B10: Cat 1: Bienes y servicios - Insumos operacionales | C10: 2246.5409 | D10: 850 | E10: ='8. Insumos y Empaque'!$J$29 -> 789.24863 | F10: =+E10-D10 -> -60.751367 | G10: =+D10*1000/$D$23 -> 0.044489029 | H10: =+E10*1000/$D$23 -> 0.0413093 | I10: =+H10-G10 -> -0.0031797286 | J10: =+H10/G10-1 -> -0.071472197 | K10: Estimación en base a proyección de demanda, desviación en base a compra real de noviembre y diciembre
A11: 8 | B11: Cat 12: Fin de vida de productos vendidos | C11: 1534.3592 | D11: 528 | E11: ='8. Insumos y Empaque'!$K$28 -> 539.38539 | F11: =+E11-D11 -> 11.385391 | G11: =+D11*1000/$D$23 -> 0.027635538 | H11: =+E11*1000/$D$23 -> 0.02823145 | I11: =+H11-G11 -> 0.00059591174 | J11: =+H11/G11-1 -> 0.02156324 | K11: Estimación en base a proyección de demanda, desviación en base a compra real de noviembre y diciembre
A12: 9 | B12: Compra de electricidad | C12: 1591.1647 | D12: 1182 | E12: ='7. Energia Electrica'!$X$16 -> 1073.2022 | F12: =+E12-D12 -> -108.79783 | G12: =+D12*1000/$D$23 -> 0.06186592 | H12: =+E12*1000/$D$23 -> 0.056171438 | I12: =+H12-G12 -> -0.005694482 | J12: =+H12/G12-1 -> -0.092045539 | K12: Cambio de metodología, cálculo 2022 considera vigencia mensual de cada instalación y nuevos criterios de estimiación
A13: 10 | B13: Cat 2: Bienes de capital | C13: 1046.8453 | D13: 607 | E13: ='10. Bienes de capital'!$J$15 -> 114.62357 | F13: =+E13-D13 -> -492.37643 | G13: =+D13*1000/$D$23 -> 0.031770401 | H13: =+E13*1000/$D$23 -> 0.0059994015 | I13: =+H13-G13 -> -0.025770999 | J13: =+H13/G13-1 -> -0.81116381
A14: 11 | B14: Cat 1: Empaque | C14: 438.6238 | D14: 204 | E14: =+'8. Insumos y Empaque'!$J$28 -> 190.49121 | F14: =+E14-D14 -> -13.508789 | G14: =+D14*1000/$D$23 -> 0.010677367 | H14: =+E14*1000/$D$23 -> 0.0099703164 | I14: =+H14-G14 -> -0.0007070505 | J14: =+H14/G14-1 -> -0.066219556 | K14: Estimación en base a proyección de demanda, desviació en base a compra real de noviembre y diciembre
A15: 12 | B15: Cat 5: Residuos generados en las operaciones | C15: 544.40704 | D15: 297 | E15: =+'9. Residuos'!$N$33 -> 0 | F15: =+E15-D15 -> -297 | G15: =+D15*1000/$D$23 -> 0.01554499 | H15: =+E15*1000/$D$23 -> 0 | I15: =+H15-G15 -> -0.01554499 | J15: =+H15/G15-1 -> -1 | K15: Estimación en base a proyección de demanda, desviación en base a generación real de noviembre y diciembre (incorporación de factor de emisión de residuos peligrosos)
A16: 14 | B16: Cat 3: Otras Emisiones energía | C16: 302.51454 | D16: 97 | E16: ='7. Energia Electrica'!$Y$16 -> 270.57411 | F16: =+E16-D16 -> 173.57411 | G16: =+D16*1000/$D$23 -> 0.0050769833 | H16: =+E16*1000/$D$23 -> 0.014161858 | I16: =+H16-G16 -> 0.0090848751 | J16: =+H16/G16-1 -> 1.7894239 | K16: Cambio de metodología, cálculo 2022 considera vigencia mensual de cada instalación y nuevos criterios de estimiación
A17: 15 | B17: Cat 3: Otras Emisiones combustibles (Transporte propio) | C17: 0 | D17: 0 | E17: 0 | F17: =+E17-D17 -> 0 | G17: =+D17*1000/$D$23 -> 0 | H17: =+E17*1000/$D$23 -> 0 | I17: =+H17-G17 -> 0 | J17: 0 | K17: Desaparece esta categoría y su impacto se refleja en las categorías de distribución y transporte troncal
A18: 16 | B18: Cat 6: Viajes de negocio | C18: 107.5348 | D18: 22 | E18: ='12. Viajes de Negocio'!$G$37 -> 66.055034 | F18: =+E18-D18 -> 44.055034 | G18: =+D18*1000/$D$23 -> 0.0011514807 | H18: =+E18*1000/$D$23 -> 0.0034573227 | I18: =+H18-G18 -> 0.002305842 | J18: =+H18/G18-1 -> 2.0025015 | K18: Cambio metodologico, estimación en base a proyección de demanda, real calculado en base a registros internos
A19: 17 | B19: Emisiones fugitivas | C19: 27.706 | D19: 19 | E19: ='11. Refrigerantes'!$J$37 -> 263.2324 | F19: =+E19-D19 -> 244.2324 | G19: =+D19*1000/$D$23 -> 0.00099446064 | H19: =+E19*1000/$D$23 -> 0.013777593 | I19: =+H19-G19 -> 0.012783132 | J19: =+H19/G19-1 -> 12.854337 | K19: Cambio metodologico, estimación en base a proyección de demanda, real calculado en base a registros internos
A20: 18 | B20: Combustión- fuentes fijas | C20: 4.0750041 | D20: 0.078 | E20: =SUM('13. Combustible Fuentes fijas'!$K$37:$L$37) -> 11.96079 | F20: =+E20-D20 -> 11.88279 | G20: =+D20*1000/$D$23 -> 4.0825226e-06 | H20: =+E20*1000/$D$23 -> 0.00062602816 | I20: =+H20-G20 -> 0.00062194563 | J20: =+H20/G20-1 -> 152.34346 | K20: Se declara una mayor cantidad de generadores y calefactores en centros de distribución a nivel nacional
B21: TOTAL | C21: =+SUM(C4:C20) -> 50284.021 | D21: =+SUM(D4:D20) -> 35923.078 | E21: =+SUM(E4:E20) -> 28791.977 | F21: =+SUM(F4:F20) -> -7131.1007 | G21: =+SUM(G4:G20) -> 1.8802151 | H21: =+SUM(H4:H20) -> 1.5069731 | I21: =+H21-G21 -> -0.37324205 | J21: =+H21/G21-1 -> -0.19851029
J22: =E21/D21-1 -> -0.19851029
B23: Total de encomiendas y valijas | C23: 32943152 | D23: 19105834 | E23: 19105834
B24: kgCO2e/pieza | C24: =+C21*1000/C23 -> 1.5263877 | D24: =+D21*1000/D23 -> 1.8802151 | E24: =+E21*1000/E23 -> 1.5069731
C25: =+C24*0.96 -> 1.4653322 | D25: =E24/D24-1 -> -0.19851029 | E25: =+E24/C25-1 -> 0.028417389
E26: =+E7+E5+E4 -> 18085
E27: =+E26/E21 -> 0.62812636
D28: =E21-D21 -> -7131.1007
E29: =D24-E24 -> 0.37324205
C31: =C7+C9 -> 11041.988 | D31: =D7+D9 -> 9671
C32: =C7+C17 -> 11041.988 | D32: =D7+D17 -> 9671

Sheet Graficos
B3: Resumen de Huella de Carbono 2021 Chilexpres
G5: *Categorías en gris no aplican para la huella de carbono de Chilexpress | AH5: Comparación 2020/2021
C6: Alcance | D6: Emisiones de GEI (tCO2-e) | E6: % | G6: Alcance | H6: Categoría | I6: Emisiones de GEI (tCO2-e) | J6: %
C7: Alcance 1 | D7: =SUM(I7:I9) -> #REF! | E7: =D7/$D$10 -> #REF! | G7: Alcance 1 | H7: Combustión- fuentes fijas | I7: =+'13. Combustible Fuentes fijas'!K37 -> 11.393384 | J7: =+I7/SUM($I$7:$I$17) -> #REF! | M7: =+D7 -> #REF!
C8: Alcance 2 | D8: =I10 -> 1073.2022 | E8: =D8/$D$10 -> #REF! | H8: Combustión- fuentes móviles | I8: #REF! | J8: =+I8/SUM($I$7:$I$17) -> #REF! | M8: =+D8 -> 1073.2022 | AI8: Medio terrestre - Petróleo 2 (Diesel) | AJ8: 5107.4999 | AL8: Categoría | AM8: 2020 | AN8: 2021 | AP8: Categoría | AQ8: 2020 | AR8: 2021
C9: Alcance 3 | D9: =SUM(I11:I17) -> #REF! | E9: =D9/$D$10 -> #REF! | H9: Emisiones fugitivas | I9: =+'11. Refrigerantes'!J37 -> 263.2324 | J9: =+I9/SUM($I$7:$I$17) -> #REF! | K9: =+C7 -> Alcance 1 | L9: =+SUM(I7:I9)/I18 -> #REF! | M9: =+I11 -> #REF! | AI9: Medio terrestre - Gasolina | AJ9: 35.729913 | AL9: Combustión- fuentes fijas | AM9: =+AJ11 -> 1.6515112 | AN9: 166.35626 | AP9: Combustión- fuentes fijas | AQ9: =+AM9 -> 1.6515112 | AR9: =+I7 -> 11.393384
C10: TOTAL | D10: =SUM(D7:D9) -> #REF! | E10: =D10/$D$10 -> #REF! | G10: Alcance 2 | H10: Compra de electricidad | I10: =+'7. Energia Electrica'!X16 -> 1073.2022 | J10: =+I10/SUM($I$7:$I$17) -> #REF! | K10: =+C8 -> Alcance 2 | L10: =+I10/I18 -> #REF! | M10: =+I12 -> 0 | AI10: Medio terrestre - Gas natural | AJ10: 1.4988028 | AL10: Combustión- fuentes móviles | AM10: =+SUM(AJ8:AJ10) -> 5144.7286 | AN10: 4652.3625 | AP10: Combustión- fuentes móviles | AQ10: =+AM10 -> 5144.7286 | AR10: =+I8 -> #REF!
C11: Emisiones indirectas transporte aéreo | D11: =+I19 -> #REF! | G11: Alcance 3 | H11: Cat 1: Compra de bienes y servicios | I11: =+SUM('4. Transporte troncal'!J25:K25,#REF!)+#REF!+'8. Insumos y Empaque'!J27 -> #REF! | J11: =+I11/SUM($I$7:$I$17) -> #REF! | K11: =+H11 -> Cat 1: Compra de bienes y servicios | L11: =+I11/$I$18 -> #REF! | M11: =+I13 -> #REF! | AI11: Generador - Petróleo 2 (Diésel) | AJ11: 1.6515112 | AL11: Emisiones fugitivas | AM11: 0 | AN11: 27.706 | AP11: Emisiones fugitivas | AQ11: =+AM11 -> 0 | AR11: =+I9 -> 263.2324
H12: Cat 2: Bienes de capital | J12: =+I12/SUM($I$7:$I$17) -> #REF! | K12: =+H12 -> Cat 2: Bienes de capital | L12: =+I12/$I$18 -> #REF! | AI12: R410A - R410A | AJ12: 0 | AL12: Compra de electricidad | AM12: =+SUM(AJ14:AJ17) -> 1501.4519 | AN12: 1950.1519 | AP12: Compra de electricidad | AQ12: =+AM12 -> 1501.4519 | AR12: =+I10 -> 1073.2022
H13: Cat 3: Otras emisiones de energía y combustibles | I13: #REF! | J13: =+I13/SUM($I$7:$I$17) -> #REF! | K13: =+H13 -> Cat 3: Otras emisiones de energía y combustibles | L13: =+I13/$I$18 -> #REF! | M13: =+#REF! -> #REF! | AI13: EMISIONES INDIRECTAS POR ENERGÍA IMPORTADA | AL13: Cat 1: Compra de bienes y servicios | AM13: =+SUM(AJ19:AJ24) -> 16114.954 | AN13: 39159.103 | AP13: Cat 1: Empaque | AQ13: =+AI31 -> 1459.6755 | AR13: =+M94 -> 1972.983
H14: Cat 5: Residuos generados en las operaciones | I14: =+SUM('9. Residuos'!N25:O25) -> 317.55459 | J14: =+I14/SUM($I$7:$I$17) -> #REF! | K14: =+H14 -> Cat 5: Residuos generados en las operaciones | L14: =+I14/$I$18 -> #REF! | M14: =+I14 -> 317.55459 | AI14: Sistema Eléctrico de Los Lagos - Sistema Eléctrico de Los Lagos | AJ14: 0 | AL14: Cat 2: Bienes de capital | AM14: 0 | AN14: 1158.1922 | AP14: Cat 1: Transporte terrestre terceros | AQ14: =+AJ19 -> 7084.2782 | AR14: =+M87 -> 10100
H15: Cat 6: Viajes de negocio | J15: =+I15/SUM($I$7:$I$17) -> #REF! | K15: =+H15 -> Cat 6: Viajes de negocio | L15: =+I15/$I$18 -> #REF! | M15: =+I15 -> 0 | AI15: Sistema Eléctrico de Aysén - Sistema Eléctrico de Aysén | AJ15: 11.469488 | AL15: Cat 3: Emisiones energía y combustibles | AM15: 0 | AN15: 510.46359 | AP15: Cat 1: Transporte aéreo | AQ15: =+AJ21 -> 7571 | AR15: =+M90 -> #REF!
H16: Cat 7: Traslado de trabajadores | I16: =+'A3- Transporte colaboradores 2'!P7 -> 0 | J16: =+I16/SUM($I$7:$I$17) -> #REF! | K16: =+H16 -> Cat 7: Traslado de trabajadores | L16: =+I16/$I$18 -> #REF! | M16: =+I16 -> 0 | AI16: Sistema Eléctrico de Magallanes - Sistema Eléctrico de Magallanes | AJ16: 16.575856 | AL16: Cat 5: Residuos generados en las operaciones | AM16: 0 | AN16: 526.68069 | AP16: Cat 1: Bienes y servicios | AQ16: 0 | AR16: =+M91+H35 -> #REF!
H17: Cat 12: Fin de vida de productos vendidos | I17: =+'8. Insumos y Empaque'!K27 -> 539.33996 | J17: =+I17/SUM($I$7:$I$17) -> #REF! | K17: =+H17 -> Cat 12: Fin de vida de productos vendidos | L17: =+I17/$I$18 -> #REF! | M17: =+#REF! -> #REF! | AI17: Sistema Eléctrico Nacional - Sistema Eléctrico Nacional | AJ17: 1473.4066 | AL17: Cat 6: Viajes de negocio | AM17: 0 | AN17: 331.45871 | AP17: Cat 2: Bienes de capital | AQ17: 0 | AR17: =+M109 -> 0
H18: TOTAL | I18: =+SUM(I7:I17) -> #REF! | J18: =+I18/SUM($I$7:$I$17) -> #REF! | M18: =+#REF! -> #REF! | AI18: OTRAS EMISIONES INDIRECTAS DE GEI | AL18: Cat 7: Traslado de trabajadores | AM18: 0 | AN18: 2397.8629 | AP18: Cat 3: Emisiones energía y combustibles | AQ18: 0 | AR18: =+I13 -> #REF!
H19: Emisiones indirectas transporte aéreo | I19: =+#REF! -> #REF! | M19: =+#REF! -> #REF! | AI19: Transporte de carga 1 - Usar FE propio | AJ19: 7084.2782 | AL19: Cat 12: Fin de vida de productos vendidos | AM19: 0 | AN19: 1.7560997 | AP19: Cat 5: Residuos generados en las operaciones | AQ19: 0 | AR19: =+I14 -> 317.55459
M20: =+#REF! -> #REF! | AI20: Transporte de carga 2 - Usar FE propio | AJ20: 0 | AL20: Cat 14: Franquicias | AM20: 0 | AN20: 357.15594 | AP20: Cat 6: Viajes de negocio | AQ20: 0 | AR20: =+I15 -> 0
L21: =+SUM(L9:L18) -> #REF! | M21: =+I17 -> 539.33996 | AI21: Productos - aéreos - Aéreo - Avión trayecto doméstico (Chile continental) | AJ21: 7571 | AL21: TOTAL | AM21: =+SUM(AM9:AM20) -> 22762.786 | AN21: 51239.25 | AP21: Cat 7: Traslado de trabajadores | AQ21: 0 | AR21: =+I16 -> 0
M22: =+I23 -> 0 | AI22: Bienes adquiridos - Papel | AJ22: 611.93409 | AL22: Emisiones indirectas transporte aéreo | AN22: 9139.2274 | AP22: Cat 12: Fin de vida de productos vendidos | AQ22: 0 | AR22: =+I17 -> 539.33996
M23: =+#REF! -> #REF! | AI23: Bienes adquiridos - Plásticos: Plástico film promedio | AJ23: 681.98326 | AP23: Cat 14: Franquicias | AQ23: 0 | AR23: =+#REF! -> #REF!
M24: =+I25 -> 0 | AI24: Bienes adquiridos - Plásticos: Polietileno de baja densidad (LDPE) y LLDPE | AJ24: 165.75816 | AQ24: =+SUM(AQ9:AQ23) -> 22762.786 | AR24: =+SUM(AR9:AR23) -> #REF!
AI25: OTRAS EMISIONES DE GEI FUERA DEL INVENTARIO
AI26: Montreal - HCFC-22/R22 | AJ26: 0
AI31: =+SUM(AJ22:AJ24) -> 1459.6755
G32: Ítem | H32: Emisiones de GEI (tCO2-e) | AT32: =+(AR24-AQ24)/AQ24 -> #REF!
G33: Transporte terrestre terceros | H33: =+SUM('4. Transporte troncal'!J25:K25) -> 11041.76 | I33: =+H33/$H$38 -> #REF!
G34: Transporte aéreo | H34: =+#REF! -> #REF! | I34: =+H34/$H$38 -> #REF!
G35: Insumos | H35: =+#REF! -> #REF! | I35: =+H35/$H$38 -> #REF!
G36: Empaque | H36: =+'8. Insumos y Empaque'!J27 -> 979.73984 | I36: =+H36/$H$38 -> #REF!
G37: Servicios | H37: =+#REF! -> #REF! | I37: =+H37/$H$38 -> #REF!
G38: Total | H38: =+SUM(H33:H37) -> #REF!
N80: =+SUM(M87:M91) -> #REF!
M81: =+M87+M88+M89 -> 21141.515
L86: Ítem | M86: Emisiones de GEI (tCO2-e)
L87: Transporte terrestre terceros local | M87: 10100 | O87: =+M87/$M$97 -> #REF! | P87: =+SUM(O87:O90) -> #REF!
L88: Transporte terrestre terceros troncal | M88: 6108 | O88: =+M88/$M$97 -> #REF!
L89: Transporte terrestre propio | M89: 4933.5149 | O89: =+M89/$M$97 -> #REF! | T89: =+M89+T108 -> 5164.1706
L90: Transporte aéreo | M90: =+#REF! -> #REF! | O90: =+M90/$M$97 -> #REF!
L91: Servicios | M91: =+H37 -> #REF! | O91: =+M91/$M$97 -> #REF!
L92: Transporte colaboradores | M92: =+I16 -> 0 | O92: =+M92/$M$97 -> #REF!
...

Sheet Categorías GHG
A1: Categoría de negocio | B1: Categorias GHG Protocol | H1: Factores de emisión | L1: Respaldo
B2: Alcance | C2: Categoria GHG Protocol | D2: Definición Protocolo GHG (OFICIAL) | E2: Incluida (SI/NO) | F2: Justificación de exclusión | H2: Fuente de información | I2: Unidad | J2: Licenciamiento | K2: link | L2: Responsable de respaldo | M2: Jefatura Responsable | N2: Tipo de respaldo | O2: Origen del dato
A3: =C3 -> Fuentes móviles (Transporte propio troncal) | B3: 1 | C3: Fuentes móviles (Transporte propio troncal) | D3: Emisiones de fuentes móviles propias o alquiladas (tanto en carretera y vehículos que no son de carretera) que se encuentran dentro de los límites del inventario de la empresa | E3: Sí | F3: incluida | H3: IPCC 2006 | I3: kg CO2e/l | J3: No | L3: Diego Maturana | M3: Andres Gruettner | N3: Facturas (COPEC-AGASNAR) Reporte de transporte troncal Plataformas de consumo (TCT, surtidor interno)
A4: =C4 -> Fuentes Fijas | B4: 1 | C4: Fuentes Fijas | D4: Fuentes que queman sólidos, líquidos o combustible gaseoso, generalmente para producir electricidad, generación de vapor o calor para fines de procesamiento de productos. | E4: Sí | F4: incluida | H4: IPCC 2006 | I4: kg CO2e/l | J4: No | L4: Felipe Villalobos | M4: Rodrigo Martinez | N4: Facturas
A5: =C5 -> Emisiones Fugitivas | B5: 1 | C5: Emisiones Fugitivas | D5: Las emisiones fugitivas de refrigeración y aire acondicionado resultan de fugas y cargas de servicio durante la vida útil del equipo y su eliminación. | E5: Sí | F5: incluida | H5: DEFRA | I5: kg CO2e/kg | J5: No | L5: Felipe Villalobos | M5: Rodrigo Martinez | N5: Facturas
A6: =C6 -> Compra de electricidad | B6: 2 | C6: Compra de electricidad | D6: Emisiones indirectas de la generación de energía comprada. | E6: Sí | F6: incluida | H6: Ministerio de energía | I6: kg CO2eq/kWh | J6: No | L6: Gustavo Guerrero / Ivana Alvear | M6: Paulina Sanchez / Sebastián Blamey | N6: Facturas Distribuidoras (CGE-CHILQUINTA-FRONTEL-SAESA-LUZ OSORNO-EDELAYSEN-EDELMAG-ENEL-EEPA-AES) Metodología de estimacion de acuerdo a criterios utilizados Certificado ERNC
A7: =C7 -> Cat.1 Distribución | B7: 3 | C7: Cat.1 Distribución | D7: Emisiones de la producción de productos comprados o adquiridos por la empresa informante en el año de informe. | E7: Sí | F7: incluida | H7: IPCC 2006 | I7: kg CO2e/l | J7: No | L7: Diego Maturana | M7: Andres Gruettner | N7: Datos medidos con instrumentos Drivin SIGO GPS Planilla
A8: =C8 -> Cat.1 Transporte Troncal - solo externo | B8: 3 | C8: Cat.1 Transporte Troncal - solo externo | E8: Sí | F8: incluida | H8: IPCC 2006 | I8: kg CO2e/l | J8: No | L8: Diego Maturana | M8: Andres Gruettner | N8: Reporte de transporte troncal
A9: =C9 -> Cat.1 Transporte Aéreo | B9: 3 | C9: Cat.1 Transporte Aéreo | E9: Sí | F9: incluida | H9: DEFRA 2021 | I9: kg CO2eq/tkm | J9: No | L9: Diego Maturana | M9: Andres Gruettner | N9: Facturas (LATAM-SKY) Calculo Vuela Neutral Latam
A10: =C10 -> Cat.1 Bienes y servicios - Compra de servicios | B10: 3 | C10: Cat.1 Bienes y servicios - Compra de servicios | E10: Sí | F10: incluida | H10: exiobase | I10: kg CO2e/USD | J10: Sí | L10: Oswaldo Caldera | M10: Germán Yañez | N10: Factura según proveedor de servicio
A11: =C11 -> Cat.1 Bienes y servicios - Insumos Operacionales | B11: 3 | C11: Cat.1 Bienes y servicios - Insumos Operacionales | E11: Sí | F11: incluida | H11: ecoinvent v3.6 | I11: kg CO2e/kg | J11: Sí | L11: Cristián Vergaray | M11: Paulina Sanchez | N11: Factura (pendiente proveedores) Base recepción de insumos)
A12: =C12 -> Cat.1 Bienes y servicios - Compra de empaques | B12: 3 | C12: Cat.1 Bienes y servicios - Compra de empaques | E12: Sí | F12: incluida | H12: ecoinvent v3.6 | I12: kg CO2e/USD | J12: Sí | L12: Cristián Vergaray | M12: Paulina Sanchez | N12: Factura (pendiente proveedores) Certificado material reciclado Base recepción de empaques
A13: =C13 -> Cat.2 Compra de bienes de capital | B13: 3 | C13: Cat.2 Compra de bienes de capital | D13: Emisiones de la producción de bienes de capital comprados o adquiridos por la empresa informante en el año de informe. | E13: Sí | F13: incluida | H13: exiobase | I13: kg CO2e/USD | J13: Sí | L13: Manuel Reyes | M13: Vanessa Luna | N13: Factura según proveedor de activo adquirido
A14: =C14 -> Cat.3 Otras emisiones de energía | B14: 3 | C14: Cat.3 Otras emisiones de energía | D14: Emisiones relacionadas con la producción de combustibles y energía comprado y consumido que no están incluidos en el alcance 2 | E14: Sí | F14: incluida | H14: MMA | I14: kg CO2eq/kWh | J14: No | L14: Gustavo Guerrero / Ivana Alvear | M14: Paulina Sanchez / Sebastián Blamey | N14: Facturas Distribuidoras (CGE-CHILQUINTA-FRONTEL-SAESA-LUZ OSORNO-EDELAYSEN-EDELMAG-ENEL-EEPA-AES) Metodología de estimacion de acuerdo a criterios utilizados Certificado ERNC
A15: =C15 -> Cat.3 Otras emisiones de combustible | B15: 3 | C15: Cat.3 Otras emisiones de combustible | E15: Sí | F15: incluida | H15: DEFRA | I15: kg CO2e/l | J15: No | L15: Diego Maturana | M15: Andres Gruettner | N15: Datos medidos con instrumentos Reporte de transporte troncal Plataformas de consumo (TCT, surtidor interno)
A16: =C16 -> Cat 4: Transporte aguas arriba | B16: 3 | C16: Cat 4: Transporte aguas arriba | D16: Emisiones del transporte y distribución de los productos adquiridos | E16: No | F16: Menos del 1% de contribución, por lo tanto, por falta de mejor información, esta categoría quedó fuera excluida. Corresponde al transporte proveedores de insumos hacia nosotros. | H16: excluida | I16: excluida | J16: excluida | L16: No aplica | M16: No aplica | N16: N/A
A17: =C17 -> Cat 5: Residuos generados en las operaciones | B17: 3 | C17: Cat 5: Residuos generados en las operaciones | D17: Emisiones de la eliminación y el tratamiento de residuos por parte de terceros generados en las operaciones propias o controladas por la empresa que informa | E17: Sí | F17: incluida | H17: Ecoinvent v3.6 | I17: kg CO2/kg | J17: Sí | L17: Claudia Escarate | M17: Constanza Bazan | N17: Estado de Pago Volta Certificado de disposición final Boleta con peso de valorización Metodología de estimación
A18: =C18 -> Cat 6: Viajes de negocio | B18: 3 | C18: Cat 6: Viajes de negocio | D18: Emisiones del transporte de empleados para actividades relacionadas con el negocio | E18: Sí | F18: incluida | H18: exiobase | I18: kg CO2eq/USD | J18: Sí | L18: Eduardo Estay | M18: Paulina Sanchez | N18: Factura (LATAM-SKY-HOSPEDAJE)
A19: =C19 -> Cat 7: Traslado de trabajadores | B19: 3 | C19: Cat 7: Traslado de trabajadores | D19: Emisiones del transporte de los empleados entre sus hogares y sus lugares de trabajo. | E19: Sí | F19: incluida | H19: ecoinvent v3.6 | I19: kg CO2e/personkm | J19: Sí | L19: Danilo Muñoz / Carlos Escarate | M19: Donna Barrera / Solange Mc Guire | N19: Encuesta de hábitos de transpore Documento Metodología de extrapolación
A20: =C20 -> Cat 8: Bienes arrendados aguas arriba | B20: 3 | C20: Cat 8: Bienes arrendados aguas arriba | D20: Emisiones provenientes de la operación de activos que son arrendados por la empresa informante | E20: No | F20: Los consumos por la operación de bienes arrendados fueron consolidados en el alcance 2 (consumo electrico). No se incluye los bienes arrendados como tal, porque no es una categoría obligatoria dentro del protocolo y la información disponible tiene alta incertidumbre. | H20: excluida | I20: excluida | J20: excluida | L20: No aplica | M20: No aplica | N20: N/A
A21: =C21 -> Cat 9: Transporte aguas abajo | B21: 3 | C21: Cat 9: Transporte aguas abajo | D21: Emisiones del transporte y distribución de productos vendidos en vehículos e instalaciones que no son propiedad ni están bajo el control de la empresa informante. | E21: No | F21: Transporte hacia clientes esta categoría no aplica, ya que corresponde al transporte hacia el consumidor cuando no lo paga la empresa, y en nuestro caso está incluido en alcance 1 y 3. | H21: excluida | I21: excluida | J21: excluida | L21: No aplica | M21: No aplica | N21: N/A
A22: =C22 -> Cat 10: Procesamiento productos vendidos: | B22: 3 | C22: Cat 10: Procesamiento productos vendidos: | D22: Emisiones del procesamiento de productos vendidospor terceros | E22: No | F22: Los productos que vendemos (embalajes) están considerados en compras de embalajes y fin de vida. | H22: excluida | I22: excluida | J22: excluida | L22: No aplica | M22: No aplica | N22: N/A
A23: =C23 -> Cat 11: Uso de productos vendidos: | B23: 3 | C23: Cat 11: Uso de productos vendidos: | D23: Emisiones por el uso de bienes y servicios vendidos por el compañía. | E23: No | F23: Los productos que vendemos (embalajes) están considerados en compras de embalajes y fin de vida. | H23: excluida | I23: excluida | J23: excluida | L23: No aplica | M23: No aplica | N23: N/A
A24: =C24 -> Cat 12: Fin de vida empaques | B24: 3 | C24: Cat 12: Fin de vida empaques | D24: Emisiones de la eliminación de residuos y el tratamiento de productos vendido por la empresa y su fin de vida | E24: Sí | F24: incluida | H24: ecoinvent v3.6 | I24: kg CO2e/kg | J24: Sí | L24: Cristián Vergaray | M24: Paulina Sanchez | N24: Factura (pendiente proveedores) Certificado material reciclado Base recepción de empaques
A25: =C25 -> Cat 13: Activos arrendados aguas abajo | B25: 3 | C25: Cat 13: Activos arrendados aguas abajo | D25: Emisiones provenientes de la operación de los activos que son propiedad de la empresa informante | E25: No | F25: No se incluyó en la medición de huella porque no es una categoría obligatoria dentro del protocolo y la información disponible tiene alta incertidumbre. | H25: excluida | I25: excluida | J25: excluida | L25: No aplica | M25: No aplica | N25: N/A
A26: =C26 -> Cat 14: Franquicias | B26: 3 | C26: Cat 14: Franquicias | D26: Emisiones de la operación de franquicias no incluidas en el alcance 1 o alcance 2 | E26: No | F26: Dada la naturaleza operacional de las franquicias en Chilexpress y el control sobre ellas, el impacto de dichas unidades se encuentra contabilizados en el alcance 2 y 3. Esto pues dado que el inmueble es de chilexpress, se considera como parte del control operacional. | H26: excluida | I26: excluida | J26: excluida | L26: No aplica | M26: No aplica | N26: N/A
A27: =C27 -> Cat 15: Inversiones: | B27: 3 | C27: Cat 15: Inversiones: | D27: Emisiones asociadas con la empresa que reporta inversiones | E27: No | F27: Corresponde a inversiones en el mercado bursátil. | H27: excluida | I27: excluida | J27: excluida | L27: No aplica | M27: No aplica | N27: N/A

Sheet Indice
A1: Criticidad de Categorías | B1: N° Cat | C1: Categorias de Negocio Huella de Carbono 2022 | D1: Area que gestiona de la categoria | E1: Area que validación de la información | F1: Presentación del área
A2: ALTA | B2: 1 | C2: Demanda | D2: Mejora Continua | E2: Sost. Operacional
B3: =B2+1 -> 2 | C3: Transporte Aéreo | D3: Transporte | E3: Ing. Operacional
B4: =B3+1 -> 3 | C4: Distribución (UM, PM, TL) (Propio y Externo) | D4: Distribución | E4: Ing. Operacional
B5: =B4+1 -> 4 | C5: Transporte Troncal (Propio y Externo) | D5: Transporte | E5: Ing. Operacional
B6: =B5+1 -> 5 | C6: Residuos | D6: Mejora Continua | E6: Seguridad y Salud Operacional / Sostenibilidad Operacional | F6: Resultados Huella CO2 Residuos
A7: MEDIA | B7: =B6+1 -> 6 | C7: Compra de bienes y servicios | D7: Finanzas | E7: Finanzas
B8: =B7+1 -> 7 | C8: Traslado de colaboradores | D8: Personas | E8: Sost. Operacional
B9: =B8+1 -> 8 | C9: Insumos Operacionales Compra de empaques y fin de vida de productos vendidos | D9: Compras Tácticas | E9: Administración / Mejora Continua
B10: =B9+1 -> 9 | C10: Energía Electrica | D10: Inmobiliaria | E10: Administración/ Mejora Continua | F10: https://docs.google.com/presentation/d/1cp8dckgiY_StKqz7z6E9pG6-RV9b4GgTvjg2w5SmnoY/edit#slide=id.g181f8695f58_0_578
A11: BAJA | B11: =B10+1 -> 10 | C11: Bienes de Capital | D11: Finanzas | E11: Finanzas
B12: =B11+1 -> 11 | C12: Viajes de negocio | D12: Operaciones | E12: Finanzas
B13: =B12+1 -> 12 | C13: Fuentes Fijas | D13: Inmobiliaria | E13: Inmobiliaria
B14: =B13+1 -> 13 | C14: Emisiones Fugitivas | D14: Inmobiliaria | E14: Inmobiliaria

Sheet Ppt
B2: Por categoría de negocio | C2: % | D2: TONELADAS CO2 | H2: ACCIONES REALIZADAS 2022
C3: 2022 | D3: 2021 | E3: 2022 | F3: Dif | G3: Dif % | H3: Acción | I3: Descripción | J3: Impacto | K3: Impacto %
B4: Transporte distribución | C4: 0.23 | D4: 10100 | E4: 6945 | F4: -3155 | G4: -0.31 | H4: Optimización de Red | I4: Optimizaciones de flota de vehículos primera y última milla según las variaciones de demanda. Reducción del 27% de kilómetros recorridos. | J4: -2.700 tCO2e
H5: Electromovilidad | I5: Incorporación de 94 vehículos eléctricos en flota primera y última milla RM. Incorporación gradual de 30 (septiembre) a 94 vehículos eléctricos (diciembre) . | J5: -100 tCO2e
B6: Transporte aéreo | C6: 0.23 | D6: 10259 | E6: 6789 | F6: -3470 | G6: -0.34
B7: Transporte troncal | C7: 0.15 | D7: 11042 | E7: 4359 | F7: -6683 | G7: -0.61 | H7: Optimización de malla troncal | I7: Optimización de rutas actuales adaptadas a demanda requerida y servicio. Reducción del 28% de kilómetros recorridos. | J7: -1.300 tCO2e
B8: Compra de servicios | C8: 0.14 | D8: 6615 | E8: 4140 | F8: -2475 | G8: -0.37
B9: Traslado de trabajadores | C9: 0.11 | D9: 4424 | E9: 3248 | F9: -1176 | G9: -0.27
B10: Energía Eléctrica | C10: 0.04 | D10: 1894 | E10: 1344 | F10: -550 | G10: -0.29 | H10: Uso de ERNC | I10: Utilización de ERNC para el CD ENEA I y IV, contrato cliente libre con AES Andes. Aumento de consumo ERNC respecto del total +1% lo que presenta a 1,42 GWh. 29% de uso de ERNC sobre el total de energía consumida | J10: -425 tCO2e
H11: Implementación Luces LED | I11: Menor consumo energético por avance en plan de implementación de luces LED. Disminución del 11% (580.438 kWh) del consumo eléctrico en las instalaciones operacionales (CD,CR,CO,OC,FR). Disminución de hasta un 20% de consumo en luminarias por unidad. Hasta el momento, 21 CDs han sido mejorados. Avance de plan de un 18% a un 77%. | J11: -200 tCO2e
B12: Insumos operacionales y embalajes | C12: 0.05 | D12: 4220 | E12: 1519 | F12: -2700 | G12: -0.64 | H12: Negociación de tarifas y menor compras de insumos y materiales | I12: Disminución de compras realizadas de insumos y embalajes. -46% de toneladas de material | J12: -1.941 tCO2e
H13: Embalajes bajos en emisiones | I13: Certificación de cajas de embalaje con un 99,76% de materiales de origen reciclado. -150 tCO2e evitadas 98% de nuestro embalaje es fabricado con 100% fibras recicladas. | J13: -150 tCO2e
B14: Residuos | C14: 0.01 | D14: 544 | E14: 318 | F14: -226 | G14: -0.42 | H14: Mejora en gestión de Puntos Limpios y Mini Puntos Limpios | I14: Mejora en la gestión de 19 puntos limpios y mini puntos limpios para la gestión de reciclaje de residuos reciclables operacionales y domiciliarios en 23 unidades operacionales a nivel nacional (CD/CR/CO/CORP). | J14: -60 tCO2e +9% Tasa de Valorización de 46% a 55%.
H15: Optimización Film y Bolsas contenedoras | I15: Reducción y control del consumo de Film (Enea) y Bolsas Contenedoras (OC nivel nacional)
B16: Otras categorías | C16: 0.04 | D16: 1186 | E16: 1235 | F16: 49 | G16: 0.04
B17: TOTAL | C17: 1 | D17: 50284 | E17: 29897 | F17: -20387 | G17: -0.41

Sheet 2022 Resumen
C2: VISTA 1
C3: Por año | D3: DISTRIBUCIÓN % | G3: TONELADAS CO2 | O3: KGCO2/pieza
D4: 2021 | E4: 2022 | F4: DIF | G4: 2021 | H4: 2022 | I4: DIF | J4: % DIF | K4: EXPLICACION | O4: 2021 | P4: 2022 | Q4: DIF | R4: % DIF | S4: EXPLICACION
D5: 1 | E5: 1 | F5: 0 | G5: =SUM(G37:G51) -> 50284.021 | H5: =SUM(H37:H51) -> 29928.615 | I5: =H5-G5 -> -20355.405 | J5: =I5/G5 -> -0.40480863 | O5: =SUM(O37:O51) -> 1.5263877 | P5: =SUM(P37:P51) -> 1.5664647 | Q5: =P5-O5 -> 0.04007708 | R5: =Q5/O5 -> 0.026256161
C7: Total de documentos, encomiendas y valijas | O7: ='1. Demanda'!N7 -> 32943152 | P7: ='1. Demanda'!N4 -> 19105834 | Q7: =+P7-O7 -> -13837318 | R7: =Q7/O7 -> -0.42003625
C10: VISTA 2
C11: Por categoria de negocio macro-agrupada | D11: DISTRIBUCIÓN % | G11: TONELADAS CO2 | O11: KGCO2/pieza
D12: 2021 | E12: 2022 | F12: DIF | G12: 2021 | H12: 2022 | I12: DIF | J12: % DIF | K12: EXPLICACION | O12: 2021 | P12: 2022 | Q12: DIF | R12: % DIF | S12: EXPLICACION
C13: Transporte | D13: =SUM(D22:D24) -> 0.62445487 | E13: =SUM(E22:E24) -> 0.6045405 | F13: =E13-D13 -> -0.019914367 | G13: =SUM(G22:G24) -> 31400.404 | H13: =SUM(H22:H24) -> 18093.06 | I13: =H13-G13 -> -13307.344 | J13: =I13/G13 -> -0.42379531 | O13: =SUM(O22:O24) -> 0.9531694 | P13: =SUM(P22:P24) -> 0.94699138 | Q13: =P13-O13 -> -0.0061780146 | R13: =Q13/O13 -> -0.0064815495
C14: Compra de servicios, insumos y energia electrica | D14: =D25+D28+D27 -> 0.2531479 | E14: =E25+E28+E27 -> 0.23399364 | F14: =E14-D14 -> -0.019154259 | G14: =G25+G28+G27 -> 12729.417 | H14: =H25+H28+H27 -> 7003.1056 | I14: =H14-G14 -> -5726.3112 | J14: =I14/G14 -> -0.44984867 | O14: =O25+O28+O27 -> 0.38640555 | P14: =P25+P28+P27 -> 0.36654278 | Q14: =P14-O14 -> -0.019862768 | R14: =Q14/O14 -> -0.051403941
C15: Otras categorias | D15: =D26+D29+D30 -> 0.12239724 | E15: =E26+E29+E30 -> 0.16146586 | F15: =E15-D15 -> 0.039068627 | G15: =G26+G29+G30 -> 6154.6845 | H15: =H26+H29+H30 -> 4832.4497 | I15: =H15-G15 -> -1322.2348 | J15: =I15/G15 -> -0.21483389 | O15: =O26+O29+O30 -> 0.18682743 | P15: =P26+P29+P30 -> 0.25293058 | Q15: =P15-O15 -> 0.066103149 | R15: =Q15/O15 -> 0.35381929
C16: TOTAL | D16: =D15+D14+D13 -> 1 | E16: =E15+E14+E13 -> 1 | F16: =E16-D16 -> 0 | G16: =G15+G14+G13 -> 50284.506 | H16: =H15+H14+H13 -> 29928.615 | I16: =H16-G16 -> -20355.89 | J16: =I16/G16 -> -0.40481436 | O16: =O15+O14+O13 -> 1.5264024 | P16: =P15+P14+P13 -> 1.5664647 | Q16: =Q15+Q14+Q13 -> 0.040062367 | R16: =Q16/O16 -> 0.026246268
C19: VISTA 3 (input) | AF19: GRAFICOS
C20: Por categoria de negocio agrupada | D20: DISTRIBUCIÓN % | G20: TONELADAS CO2 | O20: KGCO2/pieza | AF20: Categorías según impacto en toneladas | AG20: 2022 | AH20: kgCO27pieza 2022 | AI20: 2021 | AJ20: kgCO27pieza 2021 | AK20: tCO2 2022 | AL20: tCO2 2021
D21: 2021 | E21: 2022 | F21: DIF | G21: 2021 | H21: 2022 | I21: DIF | J21: % DIF | K21: EXPLICACION | L21: x ACCION | M21: x METOD | N21: x F.EXT. | O21: 2021 | P21: 2022 | Q21: DIF | R21: % DIF | S21: EXPLICACION | AF21: Transporte distribución | AG21: =H22/$H$31 -> 0.23204498 | AH21: =H22* 1000/$P$7 -> 0.36349028 | AI21: =D22 -> 0.20084797 | AJ21: =G22*1000/$O$7 -> 0.30657482 | AK21: =H22 -> 6944.7849 | AL21: =G22 -> 10099.541
C22: Transporte distribución | D22: =G22/$G$31 -> 0.20084797 | E22: =H22/$H$31 -> 0.23204498 | F22: =E22-D22 -> 0.031197009 | G22: =G37 -> 10099.541 | H22: =H37 -> 6944.7849 | I22: =-G22+H22 -> -3154.7559 | J22: =I22/G22 -> -0.31236627 | K22: 1) Optimizacion de capacidad de flota por menor demanda, sin embargo no es proporcional a la baja de demanda (-42%) por concentración de piezas (-27%) 2) Mejora metodologica en incorporación de motos y limpieza de datos (-3%) 3) Incorporacion operacion de vehiculos elecltricos (-100 ton, -1%) | L22: =I22-M22 -> -3060.1132 | M22: =0.03*I22 -> -94.642677 | O22: =G22*1000/$O$7 -> 0.30657482 | P22: =H22*1000/$P$7 -> 0.36349028 | Q22: =-O22+P22 -> 0.056915459 | R22: =Q22/O22 -> 0.18564949 | S22: 1) Aumento de km/pieza por concentración de piezas en +26% 2) Mejora en rendimiento al incorporar motos, bicicletas y peatones en la caracterización de flota (-7%). | AF22: Transporte aéreo | AG22: =H23/$H$31 -> 0.22683976 | AH22: =H23* 1000/$P$7 -> 0.35533649 | AI22: =D23 -> 0.20401664 | AJ22: =G23*1000/$O$7 -> 0.31141148 | AK22: =H23 -> 6789 | AL22: =G23 -> 10258.876
C23: Transporte aéreo | D23: =G23/$G$31 -> 0.20401664 | E23: =H23/$H$31 -> 0.22683976 | F23: =E23-D23 -> 0.022823122 | G23: =G38 -> 10258.876 | H23: =H38 -> 6789 | I23: =-G23+H23 -> -3469.8759 | J23: =I23/G23 -> -0.33823159 | K23: 1) Disminución tkm no proporcional a la baja de demanda (-24%) 2) Mejora en el factor de emisión Latam (-10%) (-984 tonCO2) | L23: =I23-M23 -> -2485.8759 | M23: -984 | O23: =G23*1000/$O$7 -> 0.31141148 | P23: =H23*1000/$P$7 -> 0.35533649 | Q23: =-O23+P23 -> 0.043925006 | R23: =Q23/O23 -> 0.14105133 | S23: Se mantiene base por concentración de entregas y menor emisión por cambio en metodología | AF23: Transporte troncal | AG23: =H24/$H$31 -> 0.14565576 | AH23: =H24* 1000/$P$7 -> 0.22816461 | AI23: =D24 -> 0.21959026 | AJ23: =G24*1000/$O$7 -> 0.33518309 | AK23: =H24 -> 4359.2752 | AL23: =G24 -> 11041.988
C24: Transporte troncal | D24: =G24/$G$31 -> 0.21959026 | E24: =H24/$H$31 -> 0.14565576 | F24: =E24-D24 -> -0.073934498 | G24: =G39 -> 11041.988 | H24: =H39 -> 4359.2752 | I24: =-G24+H24 -> -6682.7124 | J24: =I24/G24 -> -0.60520919 | K24: 1) -50% por menor demanda (no proporcional a la baja -42%), modificación/optimización malla troncal y cambio de metodologia de medición (no es posible determinar los impactos de forma independiente) 2) -11% mayor precisión en el dato de rendimiento. | L24: =I24-M24 -> -5947.614 | M24: =0.11*I24 -> -735.09836 | O24: =G24*1000/$O$7 -> 0.33518309 | P24: =H24*1000/$P$7 -> 0.22816461 | Q24: =-O24+P24 -> -0.10701848 | R24: =Q24/O24 -> -0.31928364 | S24: Aumento 15% km/pieza pero compensa con mejor rendimiento y por cambio metodologia | AF24: Compra de servicios | AG24: =H25/$H$31 -> 0.13833597 | AH24: =H25* 1000/$P$7 -> 0.21669842 | AI24: =D25 -> 0.13156094 | AJ24: =G25*1000/$O$7 -> 0.20081493 | AK24: =H25 -> 4140.204 | AL24: =G25 -> 6615.4766
C25: Compra de servicios | D25: =G25/$G$31 -> 0.13156094 | E25: =H25/$H$31 -> 0.13833597 | F25: =E25-D25 -> 0.006775034 | G25: =G40 -> 6615.4766 | H25: =H40 -> 4140.204 | I25: =-G25+H25 -> -2475.2726 | J25: =I25/G25 -> -0.37416391 | K25: 1) Disminución del gasto en mayor proporción que el gasto en pesos por aumento del tipo de cambio(-13%) 2) Menores gastos realizados en pesos (-8%) 3) Reubicación de gastos incluidos en otras categorias (-16%) (ej. transporte y arreglos) | L25: =0.08*I25 -> -198.02181 | M25: - | N25: =I25-L25 -> -2277.2508 | O25: =G25*1000/$O$7 -> 0.20081493 | P25: =H25*1000/$P$7 -> 0.21669842 | Q25: =-O25+P25 -> 0.015883494 | R25: =Q25/O25 -> 0.079095188 | S25: Reducción de emisiones totales (-37%) no proporcional a la baja de demanda (-42%) | AF25: Traslado de trabajadores | AG25: =H26/$H$31 -> 0.1085249 | AH25: =H26* 1000/$P$7 -> 0.17000043 | AI25: =D26 -> 0.087986719 | AJ25: =G26*1000/$O$7 -> 0.13430314 | AK25: =H26 -> 3248 | AL25: =G26 -> 4424.3687
C26: Traslado de colaboradores | D26: =G26/$G$31 -> 0.087986719 | E26: =H26/$H$31 -> 0.1085249 | F26: =E26-D26 -> 0.020538182 | G26: =G41 -> 4424.3687 | H26: =H41 -> 3248 | I26: =-G26+H26 -> -1176.3687 | J26: =I26/G26 -> -0.26588396 | K26: 1) Menor base de colaboradores (-20%) 2) Menor distancia recorrida por dia (declarada) por colaborador (-7%) | L26: =I26 -> -1176.3687 | O26: =G26*1000/$O$7 -> 0.13430314 | P26: =H26*1000/$P$7 -> 0.17000043 | Q26: =-O26+P26 -> 0.035697293 | R26: =Q26/O26 -> 0.26579642 | S26: Reducción de emisiones totales (-27%) no proporcinal a la baja de demanda (-42%) | AF26: Energía Electrica | AG26: =H27/$H$31 -> 0.04489938 | AH26: =H27* 1000/$P$7 -> 0.070333297 | AI26: =D27 -> 0.037659299 | AJ26: =G27*1000/$O$7 -> 0.057483244 | AK26: =H27 -> 1343.7763 | AL26: =G27 -> 1893.6792
C27: Energía Electrica | D27: =G27/$G$31 -> 0.037659299 | E27: =H27/$H$31 -> 0.04489938 | F27: =E27-D27 -> 0.0072400812 | G27: =G42+G43 -> 1893.6792 | H27: =H42+H43 -> 1343.7763 | I27: =-G27+H27 -> -549.90295 | J27: =I27/G27 -> -0.29038865 | K27: 1) Mejora de factor de emisión de matriz energetica nacional de un -23% (-18%) 2) Menor consumo electrico por instalaciones LED y menor cantidad de unidades (-11%) 3) Aumento de consumo ERNC respceto del total (+1%) | L27: =I27-N27 -> -450.92042 | N27: =0.18*I27 -> -98.982531 | O27: =G27*1000/$O$7 -> 0.057483244 | P27: =H27*1000/$P$7 -> 0.070333297 | Q27: =-O27+P27 -> 0.012850053 | R27: =Q27/O27 -> 0.22354432 | S27: Reduccion de emisiones totales (-29%) no es proporcional a la baja de demanda (-42%) por consumo fijo en instalaciones. Intensidad energetica por pieza aumenta +54%, sin embargo la mejora del factor de emisión contribuye a reducir -32% | AF27: Insumos operacionales y embalajes | AG27: =H28/$H$31 -> 0.050758287 | AH27: =H28* 1000/$P$7 -> 0.079511066 | AI27: =D28 -> 0.083927661 | AJ27: =G28*1000/$O$7 -> 0.12810738 | AK27: =H28 -> 1519.1252 | AL27: =G28 -> 4220.2609
C28: Insumos operacionales y embalajes | D28: =G28/$G$31 -> 0.083927661 | E28: =H28/$H$31 -> 0.050758287 | F28: =E28-D28 -> -0.033169375 | G28: ='8. Insumos y Empaque'!L62 -> 4220.2609 | H28: =H45+H46+H44 -> 1519.1252 | I28: =-G28+H28 -> -2701.1357 | J28: =I28/G28 -> -0.64003997 | K28: 1) Menor consumo de toneladas de material y optimización de compras de insumos y empaques (-46%) 2) Menor factor de emisión segun proporcion de uso de materiales por corrección (-18%) | L28: =I28-M28 -> -2214.9313 | M28: =0.18*I28 -> -486.20443 | O28: =G28*1000/$O$7 -> 0.12810738 | P28: =H28*1000/$P$7 -> 0.079511066 | Q28: =-O28+P28 -> -0.048596315 | R28: =Q28/O28 -> -0.37934048 | S28: 1) Menor consumo de material por pieza (-7%) 2) Menor factor de emision ponderado (-30%) | AF28: Residuos | AG28: =H29/$H$31 -> 0.0106104 | AH28: =H29* 1000/$P$7 -> 0.016620818 | AI28: =D29 -> 0.010818442 | AJ28: =G29*1000/$O$7 -> 0.016513295 | AK28: =H29 -> 317.55459 | AL28: =G29 -> 544
C29: Residuos | D29: =G29/$G$31 -> 0.010818442 | E29: =H29/$H$31 -> 0.0106104 | F29: =E29-D29 -> -0.00020804157 | G29: 544 | H29: =H47 -> 317.55459 | I29: =-G29+H29 -> -226.44541 | J29: =I29/G29 -> -0.41625995 | K29: 1) Menor compra/uso de materiales por menor demanda, mejora en tasa de valorización (recupero de residuos regiones y gestión de punto limpio Enea) (-34%) 2) Menor cantidad de colaboradores (-12%) 3) Aumento del factor de emisión ponderado por incorporación de tratamiento de residuos peligrosos (+2%) | L29: =I29-N29 -> -199.27196 | N29: =0.12*I29 -> -27.173449 | O29: =G29*1000/$O$7 -> 0.016513295 | P29: =H29*1000/$P$7 -> 0.016620818 | Q29: =-O29+P29 -> 0.0001075226 | R29: =Q29/O29 -> 0.0065112748 | S29: Disminucion absoluta de emisiones (-41,6%) no proporcional a disminución de demanda (-42%) | AF29: Otras categorías | AG29: =H30/$H$31 -> 0.042330561 | AH29: =H30* 1000/$P$7 -> 0.066309332 | AI29: =D30 -> 0.023592075 | AJ29: =G29*1000/$O$7 -> 0.016513295 | AK29: =H30 -> 1266.8951 | AL29: =G30 -> 1186.3158
C30: Otras categorías | D30: =G30/$G$31 -> 0.023592075 | E30: =H30/$H$31 -> 0.042330561 | F30: =E30-D30 -> 0.018738487 | G30: 1186.3158 | H30: =H51+H50+H48+H49 -> 1266.8951 | I30: =-G30+H30 -> 80.579286 | J30: =I30/G30 -> 0.067923976 | M30: =I30 -> 80.579286 | O30: =G30*1000/$O$7 -> 0.036010999 | P30: =H30*1000/$P$7 -> 0.066309332 | Q30: =-O30+P30 -> 0.030298333 | R30: =Q30/O30 -> 0.84136332 | AF30: TOTAL | AG30: =H31/$H$31 -> 1 | AH30: =H31* 1000/$P$7 -> 1.5664647 | AI30: =D31 -> 1 | AJ30: =G31*1000/$O$7 -> 1.5264024 | AK30: =H31 -> 29928.615 | AL30: =G31 -> 50284.506
C31: TOTAL | D31: =G31/$G$31 -> 1 | E31: =H31/$H$31 -> 1 | F31: =SUM(F22:F30) -> 0 | G31: =SUM(G22:G30) -> 50284.506 | H31: =SUM(H22:H30) -> 29928.615 | I31: =-G31+H31 -> -20355.89 | J31: =I31/G31 -> -0.40481436 | L31: =SUM(L22:L30) -> -15733.117 | M31: =SUM(M22:M30) -> -2219.3662 | N31: =SUM(N22:N30) -> -2403.4067 | O31: =G31*1000/$O$7 -> 1.5264024 | P31: =H31*1000/$P$7 -> 1.5664647 | Q31: =-O31+P31 -> 0.040062367 | R31: =Q31/O31 -> 0.026246268
L32: =L31/I31 -> 0.77290244 | M32: =M31/I31 -> 0.10902821 | N32: =N31/I31 -> 0.11806935
C34: VISTA 4
C35: Por categoria de negocio desagrupada | D35: DISTRIBUCIÓN % | G35: TONELADAS CO2 | O35: KGCO2/pieza
D36: 2021 | E36: 2022 | F36: DIF | G36: 2021 | H36: 2022 | I36: DIF | J36: % DIF | K36: EXPLICACION | O36: 2021 | P36: 2022 | Q36: DIF | R36: % DIF | S36: EXPLICACION
C37: Transporte Distribución | D37: =G37/$G$52 -> 0.2008499 | E37: =H37/$H$52 -> 0.23204498 | F37: =E37-D37 -> 0.031195073 | G37: 10099.541 | H37: ='2. Distribución'!K16 -> 6944.7849 | I37: =+H37-G37 -> -3154.7559 | J37: =I37/G37 -> -0.31236627 | K37: =K22 -> 1) Optimizacion de capacidad de flota por menor demanda, sin embargo no es proporcional a la baja de demanda (-42%) por concentración de piezas (-27%) 2) Mejora metodologica en incorporación de motos y limpieza de datos (-3%) 3) Incorporacion operacion de vehiculos elecltricos (-100 ton, -1%) | O37: =+G37*1000/$O$7 -> 0.30657482 | P37: =+H37*1000/$P$7 -> 0.36349028 | Q37: =+P37-O37 -> 0.056915459 | R37: =Q37/O37 -> 0.18564949 | S37: =S22 -> 1) Aumento de km/pieza por concentración de piezas en +26% 2) Mejora en rendimiento al incorporar motos, bicicletas y peatones en la caracterización de flota (-7%).
C38: Transporte aéreo | D38: =G38/$G$52 -> 0.20401861 | E38: =H38/$H$52 -> 0.22683976 | F38: =E38-D38 -> 0.022821156 | G38: 10258.876 | H38: ='3. Transporte aéreo'!D56 -> 6789 | I38: =+H38-G38 -> -3469.8759 | J38: =I38/G38 -> -0.33823159 | K38: =K23 -> 1) Disminución tkm no proporcional a la baja de demanda (-24%) 2) Mejora en el factor de emisión Latam (-10%) (-984 tonCO2) | O38: =+G38*1000/$O$7 -> 0.31141148 | P38: =+H38*1000/$P$7 -> 0.35533649 | Q38: =+P38-O38 -> 0.043925006 | R38: =Q38/O38 -> 0.14105133 | S38: =S23 -> Se mantiene base por concentración de entregas y menor emisión por cambio en metodología
C39: Transporte troncal | D39: =G39/$G$52 -> 0.21959238 | E39: =H39/$H$52 -> 0.14565576 | F39: =E39-D39 -> -0.073936615 | G39: 11041.988 | H39: ='4. Transporte troncal'!L12 -> 4359.2752 | I39: =+H39-G39 -> -6682.7124 | J39: =I39/G39 -> -0.60520919 | K39: =K24 -> 1) -50% por menor demanda (no proporcional a la baja -42%), modificación/optimización malla troncal y cambio de metodologia de medición (no es posible determinar los impactos de forma independiente) 2) -11% mayor precisión en el dato de rendimiento. | O39: =+G39*1000/$O$7 -> 0.33518309 | P39: =+H39*1000/$P$7 -> 0.22816461 | Q39: =+P39-O39 -> -0.10701848 | R39: =Q39/O39 -> -0.31928364 | S39: =S24 -> Aumento 15% km/pieza pero compensa con mejor rendimiento y por cambio metodologia
C40: Compra de servicios | D40: =G40/$G$52 -> 0.1315622 | E40: =H40/$H$52 -> 0.13833597 | F40: =E40-D40 -> 0.0067737658 | G40: 6615.4766 | H40: ='5. Bienes y servicios'!$O$35 -> 4140.204 | I40: =+H40-G40 -> -2475.2726 | J40: =I40/G40 -> -0.37416391 | K40: =K25 -> 1) Disminución del gasto en mayor proporción que el gasto en pesos por aumento del tipo de cambio(-13%) 2) Menores gastos realizados en pesos (-8%) 3) Reubicación de gastos incluidos en otras categorias (-16%) (ej. transporte y arreglos) | O40: =+G40*1000/$O$7 -> 0.20081493 | P40: =+H40*1000/$P$7 -> 0.21669842 | Q40: =+P40-O40 -> 0.015883494 | R40: =Q40/O40 -> 0.079095188 | S40: =S25 -> Reducción de emisiones totales (-37%) no proporcional a la baja de demanda (-42%)
C41: Traslado de colaboradores | D41: =G41/$G$52 -> 0.087987567 | E41: =H41/$H$52 -> 0.1085249 | F41: =E41-D41 -> 0.020537333 | G41: 4424.3687 | H41: ='6. Traslado colaboradores'!$L$12 -> 3248 | I41: =+H41-G41 -> -1176.3687 | J41: =I41/G41 -> -0.26588396 | K41: =K26 -> 1) Menor base de colaboradores (-20%) 2) Menor distancia recorrida por dia (declarada) por colaborador (-7%) | O41: =+G41*1000/$O$7 -> 0.13430314 | P41: =+H41*1000/$P$7 -> 0.17000043 | Q41: =+P41-O41 -> 0.035697293 | R41: =Q41/O41 -> 0.26579642 | S41: =S26 -> Reducción de emisiones totales (-27%) no proporcinal a la baja de demanda (-42%)
C42: Compra de electricidad | D42: =G42/$G$52 -> 0.031643545 | E42: =H42/$H$52 -> 0.035858731 | F42: =E42-D42 -> 0.0042151857 | G42: 1591.1647 | H42: ='7. Energia Electrica'!$X$16 -> 1073.2022 | I42: =+H42-G42 -> -517.96253 | J42: =I42/G42 -> -0.32552414 | K42: =K27 -> 1) Mejora de factor de emisión de matriz energetica nacional de un -23% (-18%) 2) Menor consumo electrico por instalaciones LED y menor cantidad de unidades (-11%) 3) Aumento de consumo ERNC respceto del total (+1%) | O42: =+G42*1000/$O$7 -> 0.048300317 | P42: =+H42*1000/$P$7 -> 0.056171438 | Q42: =+P42-O42 -> 0.0078711207 | R42: =Q42/O42 -> 0.16296209 | S42: =S27 -> Reduccion de emisiones totales (-29%) no es proporcional a la baja de demanda (-42%) por consumo fijo en instalaciones. Intensidad energetica por pieza aumenta +54%, sin embargo la mejora del factor de emisión contribuye a reducir -32%
C43: Otras emisiones energia electrica | D43: =G43/$G$52 -> 0.0060161168 | E43: =H43/$H$52 -> 0.0090406493 | F43: =E43-D43 -> 0.0030245325 | G43: 302.51454 | H43: ='7. Energia Electrica'!$Y$16 -> 270.57411 | I43: =+H43-G43 -> -31.940426 | J43: =I43/G43 -> -0.10558311 | O43: =+G43*1000/$O$7 -> 0.0091829264 | P43: =+H43*1000/$P$7 -> 0.014161858 | Q43: =+P43-O43 -> 0.0049789319 | R43: =Q43/O43 -> 0.54219447
C44: Insumos operacionales | D44: =G44/$G$52 -> 0.044677033 | E44: =H44/$H$52 -> 0.026371037 | F44: =E44-D44 -> -0.018305996 | G44: 2246.5409 | H44: ='8. Insumos y Empaque'!$J$29 -> 789.24863 | I44: =+H44-G44 -> -1457.2922 | J44: =I44/G44 -> -0.64868271 | K44: =K28 -> 1) Menor consumo de toneladas de material y optimización de compras de insumos y empaques (-46%) 2) Menor factor de emisión segun proporcion de uso de materiales por corrección (-18%) | O44: =+G44*1000/$O$7 -> 0.068194472 | P44: =+H44*1000/$P$7 -> 0.0413093 | Q44: =+P44-O44 -> -0.026885172 | R44: =Q44/O44 -> -0.39424268 | S44: =S28 -> 1) Menor consumo de material por pieza (-7%) 2) Menor factor de emision ponderado (-30%)
C45: Empaque | D45: =G45/$G$52 -> 0.0087229261 | E45: =H45/$H$52 -> 0.0063648521 | F45: =E45-D45 -> -0.002358074 | G45: 438.6238 | H45: ='8. Insumos y Empaque'!$J$28 -> 190.49121 | I45: =+H45-G45 -> -248.13259 | J45: =I45/G45 -> -0.56570708 | O45: =+G45*1000/$O$7 -> 0.013314567 | P45: =+H45*1000/$P$7 -> 0.0099703164 | Q45: =+P45-O45 -> -0.0033442504 | R45: =Q45/O45 -> -0.2511723
C46: Fin de vida empaques | D46: =G46/$G$52 -> 0.030513853 | E46: =H46/$H$52 -> 0.018022397 | F46: =E46-D46 -> -0.012491456 | G46: 1534.3592 | H46: ='8. Insumos y Empaque'!$K$28 -> 539.38539 | I46: =+H46-G46 -> -994.97385 | J46: =I46/G46 -> -0.64846212 | O46: =+G46*1000/$O$7 -> 0.046575969 | P46: =+H46*1000/$P$7 -> 0.02823145 | Q46: =+P46-O46 -> -0.01834452 | R46: =Q46/O46 -> -0.39386233
C47: Residuos | D47: =G47/$G$52 -> 0.010826641 | E47: =H47/$H$52 -> 0.0106104 | F47: =E47-D47 -> -0.00021624063 | G47: 544.40704 | H47: ='9. Residuos'!P25 -> 317.55459 | I47: =+H47-G47 -> -226.85245 | J47: =I47/G47 -> -0.41669639 | K47: =K29 -> 1) Menor compra/uso de materiales por menor demanda, mejora en tasa de valorización (recupero de residuos regiones y gestión de punto limpio Enea) (-34%) 2) Menor cantidad de colaboradores (-12%) 3) Aumento del factor de emisión ponderado por incorporación de tratamiento de residuos peligrosos (+2%) | O47: =+G47*1000/$O$7 -> 0.016525651 | P47: =+H47*1000/$P$7 -> 0.016620818 | Q47: =+P47-O47 -> 9.5166834e-05 | R47: =Q47/O47 -> 0.0057587343 | S47: =S29 -> Disminucion absoluta de emisiones (-41,6%) no proporcional a disminución de demanda (-42%)
...

Sheet 1. Demanda
A1: Demanda CXP 2022 | B1: Enero | C1: Febrero | D1: Marzo | E1: Abril | F1: Mayo | G1: Junio | H1: Julio | I1: Agosto | J1: Septiembre | K1: Octubre | L1: Noviembre | M1: Diciembre | N1: Total
A2: Encomiendas y valijas | B2: 1570029 | C2: 1405041 | D2: 1534834 | E2: 1451744 | F2: 1441651 | G2: 1522102 | H2: 1265657 | I2: 1313760 | J2: 1128292 | K2: 1374975 | L2: 1221741 | M2: 1529817 | N2: 16759643
A3: Documentos | B3: 199250 | C3: 176648 | D3: 237526 | E3: 199281 | F3: 214697 | G3: 185027 | H3: 186969 | I3: 202981 | J3: 179265 | K3: 178750 | L3: 191116 | M3: 194681 | N3: 2346191
A4: Total | B4: 1769279 | C4: 1581689 | D4: 1772360 | E4: 1651025 | F4: 1656348 | G4: 1707129 | H4: 1452626 | I4: 1516741 | J4: 1307557 | K4: 1553725 | L4: 1412857 | M4: 1724498 | N4: 19105834
A7: Demanda CXP 2021 | B7: 2647774 | C7: 2330302 | D7: 2764544 | E7: 2749646 | F7: 3536982 | G7: 3651844 | H7: 2949034 | I7: 2544053 | J7: 2337380 | K7: 2383714 | L7: 2367896 | M7: 2679983 | N7: =SUM(B7:M7) -> 32943152
A10: Demanda
A11: 2021 | B11: 32943152
A12: 2022 | B12: 19105834

Sheet 2. Distribución
A1: TRANSPORTE TERRESTRE DE TERCEROS - DISTRIBUCIÓN
B3: Por favor llene la siguiente información sobre la cantidad y tipo de combustibles consumidos para todos los vehículos de terceros durante el año calendario 2022. Indique además información de tipo de servicio, marca - modelo, rendimiento y km recorridos. Si no cuenta con la información de combustible consumido, dejar en blanco. | L3: GHG Protocolo
L4: Propiedad | M4: Alcance | N4: Directas | O4: Indirectas | P4: Total
L5: PROPIO | M5: Alcance 1 | N5: =I10 -> 1250.7378 | O5: =J10 -> 61.291681 | P5: =SUM(N5:O5) -> 1312.0295
B6: TIPO DE RESPALDOS: | C6: Facturas, registros internos de compra, respaldos de SAP, documentación con supuestos y estimaciones si aplica. | L6: EXTERNO | M6: Alcance 3 | N6: =SUM(I11:I12) -> 5361.4857 | O6: =SUM(J11:J13) -> 271.26972 | P6: =SUM(N6:O6) -> 5632.7554
M7: Total | N7: =SUM(N5:N6) -> 6612.2235 | O7: =SUM(O5:O6) -> 332.5614 | P7: =SUM(N7:O7) -> 6944.7849
B8: 2022 | I8: Directo | J8: Indirecto
B9: Tipo de vehículo | C9: Rendimiento (km/l) | D9: Km recorridos | E9: Tipo de combustible | F9: Fecha | G9: Cantidad combustible consumido (mes) | H9: Unidad | I9: ton CO2-e | J9: ton CO2-e
B10: Furgones propios | C10: 12 | D10: 5477362 | E10: Diesel vehículos todo terreno | F10: 2022 | G10: =+D10/C10 -> 456446.83 | H10: Lt | I10: =+G10*VLOOKUP(E10,'Factores Emisión EDGE'!$K$7:$L$13,2,FALSE)/1000 -> 1250.7378 | J10: =+G10*VLOOKUP(E10,'Factores Emisión EDGE'!$K$254:$L$260,2,FALSE)/1000 -> 61.291681
B11: Furgones externos | C11: 12 | D11: 23047281 | E11: Diesel vehículos todo terreno | F11: 2022 | G11: =+D11/C11 -> 1920606.8 | H11: Lt | I11: =+G11*VLOOKUP(E11,'Factores Emisión EDGE'!$K$7:$L$13,2,FALSE)/1000 -> 5262.7717 | J11: =+G11*VLOOKUP(E11,'Factores Emisión EDGE'!$K$254:$L$260,2,FALSE)/1000 -> 257.89907
B12: Motos | C12: 42 | D12: 1797759 | E12: Gasolina | F12: 2022 | G12: =+D12/C12 -> 42803.786 | H12: Lt | I12: =+G12*VLOOKUP(E12,'Factores Emisión EDGE'!$K$7:$L$13,2,FALSE)/1000 -> 98.713962 | J12: =+G12*VLOOKUP(E12,'Factores Emisión EDGE'!$K$254:$L$260,2,FALSE)/1000 -> 5.2700021 | M12: BNE
B13: Vehiculo Electrico | C13: 0 | D13: 430662 | E13: Energía Eléctrica | F13: 2022 | G13: 147209 | H13: kWh | I13: 0 | J13: =G13*D30/1000 -> 8.1006417 | M13: Gasolina | N13: =G12+G15 -> 47913.786 | O13: =H12 -> Lt
B14: Vehiculo Hibrido (Gas Natural) | C14: 7.51 | D14: =G14/C14 -> 1266.1784 | E14: Gas natural | G14: 9509 | H14: m3 | I14: =9509000*C28/1000 -> 19.911846 | J14: =9509000*D28/1000 -> 3.1627409 | M14: Gas natural | N14: =G14 -> 9509 | O14: =H14 -> m3
B15: Vehiculo Hibrido (Gasolina) | C15: Ya incluido | D15: Ya incluido | E15: Gasolina | G15: 5110 | H15: Lt | I15: =G15*C27/1000 -> 11.784667 | J15: =G15*D27/1000 -> 0.6861708 | M15: EE | N15: =G13 -> 147209 | O15: =H13 -> kWh
D16: =SUM(D9:D13) -> 30753064 | I16: =SUM(I10:I15)-I14-I15 -> 6612.2235 | J16: =SUM(J10:J15)-J14-J15 -> 332.5614 | K16: =J16+I16 -> 6944.7849 | M16: Diesel | N16: =G10+G11 -> 2377053.6 | O16: =H11 -> Lt
B19: 2021 | I19: Directo | J19: Indirecto | M19: Rendimiento 7,51 km/m3
B20: Tipo de vehículo | C20: Rendimiento (km/l) | D20: Km recorridos | E20: Tipo de combustible | F20: Fecha | G20: Cantidad combustible consumido (mes) | H20: Unidad | I20: ton CO2-e | J20: ton CO2-e
B21: FURGON | C21: 12 | D21: 42162803 | E21: Diesel vehículos todo terreno | F21: 2021 | G21: =D21/C21 -> 3513566.9 | H21: Lt | I21: =+G21*VLOOKUP(E21,'Factores Emisión EDGE'!$K$7:$L$13,2,FALSE)/1000 -> 9627.739 | J21: =+G21*VLOOKUP(E21,'Factores Emisión EDGE'!$K$254:$L$260,2,FALSE)/1000 -> 471.80177
I22: =+SUM(I21) -> 9627.739 | J22: =+SUM(J21) -> 471.80177 | K22: =J22+I22 -> 10099.541
B25: Factor de Emisión según combustible | C25: Directas | D25: Indirectas | E25: Totales | F25: Unidad de medida
B26: Diesel | C26: 2.740161 | D26: 0.12312 | E26: =D26+C26 -> 2.863281 | F26: kgCO2/l
B27: Gasolina | C27: 2.306197 | D27: 0.13428 | E27: =D27+C27 -> 2.440477 | F27: kgCO2/l
B28: Gas natural | C28: 0.002094 | D28: 0.000332605 | E28: =D28+C28 -> 0.002426605 | F28: kgCO2/l
B29: Energía Electrica (SEN) | C29: 0.3006 | D29: 0.055028169 | E29: =D29+C29 -> 0.35562817 | F29: kgCO2/kWh | G29: SEN: Sistema Eléctrico Nacional
B30: Energia Electrica (ERNC) | C30: 0 | D30: 0.055028169 | E30: =D30+C30 -> 0.055028169 | F30: kgCO2/kWh | G30: SEN: Sistema Eléctrico Nacional
B31: Energia Electrica Punta Arenas (SEM) | C31: 0.59279167 | D31: 0.055028169 | E31: =D31+C31 -> 0.64781984 | F31: kgCO2/kWh | G31: SEM: Sistema Eléctrico Magallanes
B32: Energia Electrica Aysén (SEA) | C32: 0.7245 | D32: 0.055028169 | E32: =D32+C32 -> 0.77952817 | F32: kgCO2/kWh | G32: SEA: Sistema Eléctrico Aysen
B36: Resumen
B37: Distribución | C37: 2021 | D37: 2022 | F37: Diferencia | G37: Explicacion
B38: kilometros recorridos | C38: =D21 -> 42162803 | D38: =SUM(D10:D13) -> 30753064 | E38: =D38-C38 -> -11409739 | F38: =D38/C38-1 -> -0.27061149 | G38: Se disminuyen los kilometros recorridos por la red por menor demanda, sin embargo no es proporcional por concentración de piezas.
B39: km/pieza | C39: =D21/C54 -> 1.2798655 | D39: =D38/C55 -> 1.6096164 | E39: 0.33 | F39: =D39/C39-1 -> 0.257645 | G39: Aumento de km/pieza por base de coberturas para entregas (concentración de piezas)
B40: factor de ajuste | C40: 0.761 | D40: 0.706 | E40: =D40-C40 -> -0.055 | F40: =D40-C40 -> -0.055 | G40: disminución de factor
B41: Entregas por planilla | C41: 0.0558 | D41: 0.0278 | E41: =D41-C41 -> -0.028 | F41: =D41-C41 -> -0.028 | G41: disminución de entregas por planilla
B42: Rendimiento promedio | C42: =C43 -> 12 | D42: =D38/SUM(G10:G12) -> 12.708627 | E42: 0.71 | F42: =D42/C42-1 -> 0.059052226
B43: Rendimiento furgon | C43: 12 | D43: 12 | F43: =C43-D43 -> 0 | G43: se mantiene
B44: Rendimiento motos | C44: No aplica | D44: 42 | F44: No hay en 2021 | G44: se incorporan motos
B45: kms VE (descontados) | C45: 0 | D45: 430662 | E45: =D45-C45 -> 430662 | F45: No hay en 2021 | G45: Inicio operacion electrica septiembre 2022
B46: Piezas entregadas VE 2022 | E46: =D46-C46 -> 0 | F46: No hay en 2021 | G46: Inicio operacion electrica septiembre 2022
B47: tCO2 evitado VE | C47: 0 | D47: 98 | E47: =D47-C47 -> 98 | F47: No hay en 2021 | G47: inicio operacion electrica septiembre 2022
B48: kgCO2/pieza evitado VE | C48: 0 | D48: =D47*1000/C55 -> 0.0051293233 | E48: =D48-C48 -> 0.0051293233 | F48: No hay en 2021 | G48: inicio operacion electrica septiembre 2022
...

Sheet 3. Transporte aéreo
A1: TRANSPORTE AÉREO
B3: Por favor llene la siguiente información sobre el peso transportado y km recorridos o bien indique origen y destino, para todo el transporte de carga aéreo realizado durante el año calendario 2021.
B7: TIPO DE RESPALDOS: | C7: Facturas, respaldos de SAP u otros.
B9: Transporte aéreo
